#VRML_SIM V6.0 utf8
WorldInfo {
  info [
    "Description"
    "Author: first name last name <e-mail>"
    "Date: DD MMM YYYY"
  ]
  physics "no_lift"
  basicTimeStep 1
  runRealTime TRUE
  contactProperties [
    DEF CONTACT ContactProperties {
    }
  ]
}
Viewpoint {
  orientation 0 1 0 -1.57
  position -6.54333 1.2 0
}
Background {
  skyColor [
    0.658824 0.827451 1
  ]
}
DirectionalLight {
  direction 0 -1 1
  castShadows TRUE
}
DirectionalLight {
}

DEF REGIS Supervisor {
  translation 0 1.53 0
  rotation 1 0 0 0.2
  children [
    Transform {
      rotation 1 0 0 0
      children [
        DEF FOOT Group {
          children [
            Transform {
              children [
                Shape {
                  geometry Capsule {
                    height 0.16
                    radius 0.05
                  }
                }
              ]
            }
          ]
        }
        DEF SHIN Group {
          children [
            Transform {
              translation 0 -0.25 0
              children [
                DEF APPEARANCE_SHIN_LEFT Shape {
                  geometry Capsule {
                    height 0.35
                    radius 0.05
                  }
                }
              ]
            }
          ]
        }
        DEF THIGH Group {
          children [
            Transform {
              translation 0 -0.25 0
              children [
                DEF APPEARANCE_THIGH_LEFT Shape {
                  geometry Capsule {
                    height 0.35
                    radius 0.08
                  }
                }
              ]
            }
          ]
        }
        DEF JOINT Shape {
          appearance Appearance {
            material Material {
              diffuseColor 0 0 1
              transparency 0.01
            }
          }
          geometry Sphere {
            radius 0.07
          }
        }
      ]
    }
    DEF RECEIVER Receiver {
      name "RECEIVER"
      channel 1
    }
    DEF EMITTER Emitter {
      name "EMITTER"
    }
    DEF TRUNK Transform {
      translation 0 -0.19 0
      children [
        DEF TRUNK Shape {
          geometry Capsule {
            height 0.4
            radius 0.13
          }
        }
      ]
    }
    DEF LEFT_LEG Transform {
      translation 0.08 -0.4 0
      children [
        DEF LEFT_HIP HingeJoint {
          jointParameters HingeJointParameters {
          }
          device RotationalMotor {
            name "HIP_LEFT"
            maxTorque 200
          }
          endPoint DEF LEFT_THIGH Solid {
            children [
              Transform {
                translation 0 -0.5 0
                children [
                  DEF LEFT_KNEE HingeJoint {
                    jointParameters HingeJointParameters {
                    }
                    device RotationalMotor {
                      name "KNEE_LEFT"
                      maxTorque 200
                    }
                    endPoint DEF LEFT_SHIN Solid {
                      rotation 1 0 0 0
                      children [
                        USE JOINT
                        USE SHIN
                        Transform {
                          translation 0 -0.5 0
                          children [
                            DEF LEFT_ANKLE HingeJoint {
                              jointParameters HingeJointParameters {
                              }
                              device RotationalMotor {
                                name "ANKLE_LEFT"
                                maxTorque 200
                              }
                              endPoint DEF LEFT_FOOT Solid {
                                rotation -1 0 0 0.085
                                children [
                                  Transform {
                                    translation 0 -0.075 0.06
                                    rotation 1 0 0 1.57
                                    children [
                                      DEF SENSOR_HEEL_LEFT TouchSensor {
                                        name "SENSOR_HEEL_LEFT"
                                        boundingObject Transform {
                                          translation 0 -0.075 0
                                          rotation 1 0 0 0
                                          children [
                                            Sphere {
                                              radius 0.05
                                            }
                                          ]
                                        }
                                        physics Physics {
                                          density -1
                                          mass 1e-08
                                        }
                                        type "force-3d"
                                        lookupTable []
                                      }
                                      DEF SENSOR_HEEL_LEFT2 TouchSensor {
                                        translation 0 -0.15 0
                                        rotation 1 0 0 3.14
                                        name "SENSOR_HEEL_LEFT2"
                                        boundingObject Transform {
                                          translation 0 -0.075 0
                                          rotation 1 0 0 0
                                          children [
                                            Sphere {
                                              radius 0.05
                                            }
                                          ]
                                        }
                                        physics Physics {
                                          density -1
                                          mass 1e-08
                                        }
                                        type "force-3d"
                                        lookupTable []
                                      }
                                      DEF SENSOR_TOE_LEFT TouchSensor {
                                        name "SENSOR_TOE_LEFT"
                                        boundingObject Transform {
                                          translation 0 0.075 0
                                          rotation 1 0 0 1.57
                                          children [
                                            Sphere {
                                              radius 0.05
                                            }
                                          ]
                                        }
                                        physics Physics {
                                          density -1
                                          mass 1e-08
                                        }
                                        type "force-3d"
                                        lookupTable []
                                      }
                                      DEF SENSOR_TOE_LEFT2 TouchSensor {
                                        translation 0 0.15 0
                                        rotation 1 0 0 3.14
                                        name "SENSOR_TOE_LEFT2"
                                        boundingObject Transform {
                                          translation 0 0.075 0
                                          rotation 1 0 0 1.57
                                          children [
                                            Sphere {
                                              radius 0.05
                                            }
                                          ]
                                        }
                                        physics Physics {
                                          density -1
                                          mass 1e-08
                                        }
                                        type "force-3d"
                                        lookupTable []
                                      }
                                      USE FOOT
                                    ]
                                  }
                                  USE JOINT
                                ]
                                physics Physics {
                                  density -1
                                  mass 1.25
                                  centerOfMass [
                                    0 0 0.02
                                  ]
                                  inertiaMatrix [
                                    0.005 0.005 0.005
                                    0 0 0
                                  ]
                                }
                              }
                            }
                          ]
                        }
                      ]
                      boundingObject USE SHIN
                      physics Physics {
                        density -1
                        mass 3.5
                        centerOfMass [
                          0 -0.2 0
                        ]
                        inertiaMatrix [
                          0.05 0.05 0.05
                          0 0 0
                        ]
                      }
                    }
                  }
                ]
              }
              USE JOINT
              USE THIGH
            ]
            boundingObject USE THIGH
            physics Physics {
              density -1
              mass 8.5
              centerOfMass [
                0 -0.2 0
              ]
              inertiaMatrix [
                0.15 0.15 0.15
                0 0 0
              ]
            }
          }
        }
      ]
    }
    DEF RIGHT_LEG Transform {
      translation -0.08 -0.4 0
      children [
        DEF RIGHT_HIP HingeJoint {
          jointParameters HingeJointParameters {
          }
          device RotationalMotor {
            name "HIP_RIGHT"
            maxVelocity 100
            maxTorque 200
          }
          endPoint DEF RIGHT_THIGH Solid {
            children [
              Transform {
                translation 0 -0.5 0
                children [
                  DEF RIGHT_KNEE HingeJoint {
                    jointParameters HingeJointParameters {
                    }
                    device RotationalMotor {
                      name "KNEE_RIGHT"
                      controlPID 100 0 0
                      maxVelocity 100
                      maxTorque 200
                    }
                    endPoint DEF RIGHT_SHIN Solid {
                      rotation 1 0 0 0
                      children [
                        USE JOINT
                        USE SHIN
                        Transform {
                          translation 0 -0.5 0
                          children [
                            DEF RIGHT_ANKLE HingeJoint {
                              jointParameters HingeJointParameters {
                              }
                              device RotationalMotor {
                                name "ANKLE_RIGHT"
                                controlPID 100 0 0
                                maxVelocity 100
                                maxTorque 200
                              }
                              endPoint DEF RIGHT_FOOT Solid {
                                rotation -1 0 0 0.085
                                children [
                                  Transform {
                                    translation 0 -0.075 0.06
                                    rotation 1 0 0 1.57
                                    children [
                                      DEF SENSOR_HEEL_RIGHT TouchSensor {
                                        name "SENSOR_HEEL_RIGHT"
                                        boundingObject Transform {
                                          translation 0 -0.075 0
                                          rotation 1 0 0 0
                                          children [
                                            Sphere {
                                              radius 0.05
                                            }
                                          ]
                                        }
                                        physics Physics {
                                          density -1
                                          mass 1e-08
                                        }
                                        type "force-3d"
                                        lookupTable []
                                      }
                                      DEF SENSOR_HEEL_RIGHT2 TouchSensor {
                                        translation 0 -0.15 0
                                        rotation 1 0 0 3.14
                                        name "SENSOR_HEEL_RIGHT2"
                                        boundingObject Transform {
                                          translation 0 -0.075 0
                                          rotation 1 0 0 0
                                          children [
                                            Sphere {
                                              radius 0.05
                                            }
                                          ]
                                        }
                                        physics Physics {
                                          density -1
                                          mass 1e-08
                                        }
                                        type "force-3d"
                                        lookupTable []
                                      }
                                      DEF SENSOR_TOE_RIGHT TouchSensor {
                                        rotation 1 0 0 0
                                        name "SENSOR_TOE_RIGHT"
                                        boundingObject Transform {
                                          translation 0 0.075 0
                                          rotation 1 0 0 1.57
                                          children [
                                            Sphere {
                                              radius 0.05
                                            }
                                          ]
                                        }
                                        physics Physics {
                                          density -1
                                          mass 1e-08
                                        }
                                        type "force-3d"
                                        lookupTable []
                                      }
                                      DEF SENSOR_TOE_RIGHT2 TouchSensor {
                                        translation 0 0.15 0
                                        rotation 1 0 0 3.14
                                        name "SENSOR_TOE_RIGHT2"
                                        boundingObject Transform {
                                          translation 0 0.075 0
                                          rotation 1 0 0 1.57
                                          children [
                                            Sphere {
                                              radius 0.05
                                            }
                                          ]
                                        }
                                        physics Physics {
                                          density -1
                                          mass 1e-08
                                        }
                                        type "force-3d"
                                        lookupTable []
                                      }
                                      USE FOOT
                                    ]
                                  }
                                  USE JOINT
                                ]
                                physics Physics {
                                  density -1
                                  mass 1.25
                                  centerOfMass [
                                    0 0 0.02
                                  ]
                                  inertiaMatrix [
                                    0.005 0.005 0.005
                                    0 0 0
                                  ]
                                }
                              }
                            }
                          ]
                        }
                      ]
                      boundingObject USE SHIN
                      physics Physics {
                        density -1
                        mass 3.5
                        centerOfMass [
                          0 -0.2 0
                        ]
                        inertiaMatrix [
                          0.05 0.05 0.05
                          0 0 0
                        ]
                      }
                    }
                  }
                ]
              }
              USE JOINT
              USE THIGH
            ]
            boundingObject USE THIGH
            physics Physics {
              density -1
              mass 8.5
              centerOfMass [
                0 -0.2 0
              ]
              inertiaMatrix [
                0.15 0.15 0.15
                0 0 0
              ]
            }
          }
        }
      ]
    }
  ]
  name "REGIS"
  boundingObject DEF TRUNK Transform {
    translation 0 -0.19 0
    children [
      DEF TRUNK Shape {
        geometry Capsule {
          height 0.4
          radius 0.13
        }
      }
    ]
  }
  physics Physics {
    density -1
    mass 53.5
    centerOfMass [
      0 -0.05 0
    ]
    inertiaMatrix [
      3 3 3
      0 0 0
    ]
  }
  controller "version52_wbt7"
  controllerArgs "settings_jw_notf.xml sample"
}


DEF GROUND Solid {
  translation 0.0 0 0
  children [
    DEF APPEARANCE_GROUND Transform {
      translation 0 0 114
      children [
        Shape {
          appearance Appearance {
            material Material {
              diffuseColor 1 1 1
            }
            texture ImageTexture {
              url [
                "textures/ground.jpg"
              ]
            }
            textureTransform TextureTransform {
              scale 2 462
            }
          }
          geometry Plane {
            size 1 231
          }
        }
      ]
    }
  ]
  name "GROUND"
  boundingObject Plane {
  }
}

DEF WAVE1_1 Solid {
  translation -0.35 0 9.93711163781
  children [
    Shape {
      appearance Appearance {
        material Material {
        }
        texture ImageTexture {
          url [
            "textures/wood.jpg"
          ]
        }
        textureTransform TextureTransform {
          rotation 1.571
        }
      }
      geometry DEF GWAVE1_1  ElevationGrid{
        height [
          0.0, 0.0, 0.00999987500234, 0.00999987500234
        ]
        xDimension 2
        xSpacing 0.7
        zDimension 2
        zSpacing 2.0
        thickness 0
      }
    }
  ]
  boundingObject USE GWAVE1_1
}
DEF WAVE2_1 Solid {
  translation -0.35 0 11.9371116378
  children [
    Shape {
      appearance Appearance {
        material Material {
        }
        texture ImageTexture {
          url [
            "textures/wood.jpg"
          ]
        }
        textureTransform TextureTransform {
          rotation 1.571
        }
      }
      geometry DEF GWAVE2_1  ElevationGrid{
        height [
          0.00999987500234, 0.00999987500234, 0.0299988750773, 0.0299988750773
        ]
        xDimension 2
        xSpacing 0.7
        zDimension 2
        zSpacing 2.0
        thickness 0
      }
    }
  ]
  boundingObject USE GWAVE2_1
}
DEF WAVE3_1 Solid {
  translation -0.35 0 13.9371116378
  children [
    Shape {
      appearance Appearance {
        material Material {
        }
        texture ImageTexture {
          url [
            "textures/wood.jpg"
          ]
        }
        textureTransform TextureTransform {
          rotation 1.571
        }
      }
      geometry DEF GWAVE3_1  ElevationGrid{
        height [
          0.0299988750773, 0.0299988750773, 0.0599955006468, 0.0599955006468
        ]
        xDimension 2
        xSpacing 0.7
        zDimension 2
        zSpacing 2.0
        thickness 0
      }
    }
  ]
  boundingObject USE GWAVE3_1
}
DEF WAVE4_1 Solid {
  translation -0.35 0 15.9371116378
  children [
    Shape {
      appearance Appearance {
        material Material {
        }
        texture ImageTexture {
          url [
            "textures/wood.jpg"
          ]
        }
        textureTransform TextureTransform {
          rotation 1.571
        }
      }
      geometry DEF GWAVE4_1  ElevationGrid{
        height [
          0.0599955006468, 0.0599955006468, 0.099987503046, 0.099987503046
        ]
        xDimension 2
        xSpacing 0.7
        zDimension 2
        zSpacing 2.0
        thickness 0
      }
    }
  ]
  boundingObject USE GWAVE4_1
}
DEF WAVE5_1 Solid {
  translation -0.35 0 17.9371116378
  children [
    Shape {
      appearance Appearance {
        material Material {
        }
        texture ImageTexture {
          url [
            "textures/wood.jpg"
          ]
        }
        textureTransform TextureTransform {
          rotation 1.571
        }
      }
      geometry DEF GWAVE5_1  ElevationGrid{
        height [
          0.099987503046, 0.099987503046, 0.149971885366, 0.149971885366
        ]
        xDimension 2
        xSpacing 0.7
        zDimension 2
        zSpacing 2.0
        thickness 0
      }
    }
  ]
  boundingObject USE GWAVE5_1
}
DEF WAVE6_1 Solid {
  translation -0.35 0 19.9371116378
  children [
    Shape {
      appearance Appearance {
        material Material {
        }
        texture ImageTexture {
          url [
            "textures/wood.jpg"
          ]
        }
        textureTransform TextureTransform {
          rotation 1.571
        }
      }
      geometry DEF GWAVE6_1  ElevationGrid{
        height [
          0.149971885366, 0.149971885366, 0.209944903578, 0.209944903578
        ]
        xDimension 2
        xSpacing 0.7
        zDimension 2
        zSpacing 2.0
        thickness 0
      }
    }
  ]
  boundingObject USE GWAVE6_1
}
DEF WAVE7_1 Solid {
  translation -0.35 0 21.9371116378
  children [
    Shape {
      appearance Appearance {
        material Material {
        }
        texture ImageTexture {
          url [
            "textures/wood.jpg"
          ]
        }
        textureTransform TextureTransform {
          rotation 1.571
        }
      }
      geometry DEF GWAVE7_1  ElevationGrid{
        height [
          0.209944903578, 0.209944903578, 0.279902067929, 0.279902067929
        ]
        xDimension 2
        xSpacing 0.7
        zDimension 2
        zSpacing 2.0
        thickness 0
      }
    }
  ]
  boundingObject USE GWAVE7_1
}
DEF WAVE8_1 Solid {
  translation -0.35 0 23.9371116378
  children [
    Shape {
      appearance Appearance {
        material Material {
        }
        texture ImageTexture {
          url [
            "textures/wood.jpg"
          ]
        }
        textureTransform TextureTransform {
          rotation 1.571
        }
      }
      geometry DEF GWAVE8_1  ElevationGrid{
        height [
          0.279902067929, 0.279902067929, 0.359838144627, 0.359838144627
        ]
        xDimension 2
        xSpacing 0.7
        zDimension 2
        zSpacing 2.0
        thickness 0
      }
    }
  ]
  boundingObject USE GWAVE8_1
}
DEF WAVE9_1 Solid {
  translation -0.35 0 25.9371116378
  children [
    Shape {
      appearance Appearance {
        material Material {
        }
        texture ImageTexture {
          url [
            "textures/wood.jpg"
          ]
        }
        textureTransform TextureTransform {
          rotation 1.571
        }
      }
      geometry DEF GWAVE9_1  ElevationGrid{
        height [
          0.359838144627, 0.359838144627, 0.44974715779, 0.44974715779
        ]
        xDimension 2
        xSpacing 0.7
        zDimension 2
        zSpacing 2.0
        thickness 0
      }
    }
  ]
  boundingObject USE GWAVE9_1
}
DEF WAVE10_1 Solid {
  translation -0.35 0 27.9371116378
  children [
    Shape {
      appearance Appearance {
        material Material {
        }
        texture ImageTexture {
          url [
            "textures/wood.jpg"
          ]
        }
        textureTransform TextureTransform {
          rotation 1.571
        }
      }
      geometry DEF GWAVE10_1  ElevationGrid{
        height [
          0.44974715779, 0.44974715779, 0.549622391677, 0.549622391677
        ]
        xDimension 2
        xSpacing 0.7
        zDimension 2
        zSpacing 2.0
        thickness 0
      }
    }
  ]
  boundingObject USE GWAVE10_1
}
DEF WAVE11_1 Solid {
  translation -0.35 0 29.9371116378
  children [
    Shape {
      appearance Appearance {
        material Material {
        }
        texture ImageTexture {
          url [
            "textures/wood.jpg"
          ]
        }
        textureTransform TextureTransform {
          rotation 1.571
        }
      }
      geometry DEF GWAVE11_1  ElevationGrid{
        height [
          0.549622391677, 0.549622391677, 0.659456393192, 0.659456393192
        ]
        xDimension 2
        xSpacing 0.7
        zDimension 2
        zSpacing 2.0
        thickness 0
      }
    }
  ]
  boundingObject USE GWAVE11_1
}
DEF WAVE12_1 Solid {
  translation -0.35 0 31.9371116378
  children [
    Shape {
      appearance Appearance {
        material Material {
        }
        texture ImageTexture {
          url [
            "textures/wood.jpg"
          ]
        }
        textureTransform TextureTransform {
          rotation 1.571
        }
      }
      geometry DEF GWAVE12_1  ElevationGrid{
        height [
          0.659456393192, 0.659456393192, 0.779240974648, 0.779240974648
        ]
        xDimension 2
        xSpacing 0.7
        zDimension 2
        zSpacing 2.0
        thickness 0
      }
    }
  ]
  boundingObject USE GWAVE12_1
}
DEF WAVE13_1 Solid {
  translation -0.35 0 33.9371116378
  children [
    Shape {
      appearance Appearance {
        material Material {
        }
        texture ImageTexture {
          url [
            "textures/wood.jpg"
          ]
        }
        textureTransform TextureTransform {
          rotation 1.571
        }
      }
      geometry DEF GWAVE13_1  ElevationGrid{
        height [
          0.779240974648, 0.779240974648, 0.908967216813, 0.908967216813
        ]
        xDimension 2
        xSpacing 0.7
        zDimension 2
        zSpacing 2.0
        thickness 0
      }
    }
  ]
  boundingObject USE GWAVE13_1
}
DEF WAVE14_1 Solid {
  translation -0.35 0 35.9371116378
  children [
    Shape {
      appearance Appearance {
        material Material {
        }
        texture ImageTexture {
          url [
            "textures/wood.jpg"
          ]
        }
        textureTransform TextureTransform {
          rotation 1.571
        }
      }
      geometry DEF GWAVE14_1  ElevationGrid{
        height [
          0.908967216813, 0.908967216813, 1.04862547221, 1.04862547221
        ]
        xDimension 2
        xSpacing 0.7
        zDimension 2
        zSpacing 2.0
        thickness 0
      }
    }
  ]
  boundingObject USE GWAVE14_1
}
DEF WAVE15_1 Solid {
  translation -0.35 0 37.9371116378
  children [
    Shape {
      appearance Appearance {
        material Material {
        }
        texture ImageTexture {
          url [
            "textures/wood.jpg"
          ]
        }
        textureTransform TextureTransform {
          rotation 1.571
        }
      }
      geometry DEF GWAVE15_1  ElevationGrid{
        height [
          1.04862547221, 1.04862547221, 1.1982053687, 1.1982053687
        ]
        xDimension 2
        xSpacing 0.7
        zDimension 2
        zSpacing 2.0
        thickness 0
      }
    }
  ]
  boundingObject USE GWAVE15_1
}
DEF WAVE16_1 Solid {
  translation -0.35 0 39.9371116378
  children [
    Shape {
      appearance Appearance {
        material Material {
        }
        texture ImageTexture {
          url [
            "textures/wood.jpg"
          ]
        }
        textureTransform TextureTransform {
          rotation 1.571
        }
      }
      geometry DEF GWAVE16_1  ElevationGrid{
        height [
          1.1982053687, 1.1982053687, 1.35769581326, 1.35769581326
        ]
        xDimension 2
        xSpacing 0.7
        zDimension 2
        zSpacing 2.0
        thickness 0
      }
    }
  ]
  boundingObject USE GWAVE16_1
}
DEF WAVE17_1 Solid {
  translation -0.35 0 41.9371116378
  children [
    Shape {
      appearance Appearance {
        material Material {
        }
        texture ImageTexture {
          url [
            "textures/wood.jpg"
          ]
        }
        textureTransform TextureTransform {
          rotation 1.571
        }
      }
      geometry DEF GWAVE17_1  ElevationGrid{
        height [
          1.35769581326, 1.35769581326, 1.52708499614, 1.52708499614
        ]
        xDimension 2
        xSpacing 0.7
        zDimension 2
        zSpacing 2.0
        thickness 0
      }
    }
  ]
  boundingObject USE GWAVE17_1
}
DEF WAVE18_1 Solid {
  translation -0.35 0 43.9371116378
  children [
    Shape {
      appearance Appearance {
        material Material {
        }
        texture ImageTexture {
          url [
            "textures/wood.jpg"
          ]
        }
        textureTransform TextureTransform {
          rotation 1.571
        }
      }
      geometry DEF GWAVE18_1  ElevationGrid{
        height [
          1.52708499614, 1.52708499614, 1.70636039513, 1.70636039513
        ]
        xDimension 2
        xSpacing 0.7
        zDimension 2
        zSpacing 2.0
        thickness 0
      }
    }
  ]
  boundingObject USE GWAVE18_1
}
DEF WAVE19_1 Solid {
  translation -0.35 0 45.9371116378
  children [
    Shape {
      appearance Appearance {
        material Material {
        }
        texture ImageTexture {
          url [
            "textures/wood.jpg"
          ]
        }
        textureTransform TextureTransform {
          rotation 1.571
        }
      }
      geometry DEF GWAVE19_1  ElevationGrid{
        height [
          1.70636039513, 1.70636039513, 1.89550878019, 1.89550878019
        ]
        xDimension 2
        xSpacing 0.7
        zDimension 2
        zSpacing 2.0
        thickness 0
      }
    }
  ]
  boundingObject USE GWAVE19_1
}
DEF WAVE20_1 Solid {
  translation -0.35 0 47.9371116378
  children [
    Shape {
      appearance Appearance {
        material Material {
        }
        texture ImageTexture {
          url [
            "textures/wood.jpg"
          ]
        }
        textureTransform TextureTransform {
          rotation 1.571
        }
      }
      geometry DEF GWAVE20_1  ElevationGrid{
        height [
          1.89550878019, 1.89550878019, 2.09451621823, 2.09451621823
        ]
        xDimension 2
        xSpacing 0.7
        zDimension 2
        zSpacing 2.0
        thickness 0
      }
    }
  ]
  boundingObject USE GWAVE20_1
}
